2021-08-18 13:11:56,319 ERROR: Exception on /auth/login [GET][in $(pathname)s: 1454]
Traceback (most recent call last):
  File "D:\Python\flask_sait\venv\lib\site-packages\flask\app.py", line 2070, in wsgi_app
    response = self.full_dispatch_request()
  File "D:\Python\flask_sait\venv\lib\site-packages\flask\app.py", line 1515, in full_dispatch_request
    rv = self.handle_user_exception(e)
  File "D:\Python\flask_sait\venv\lib\site-packages\flask\app.py", line 1513, in full_dispatch_request
    rv = self.dispatch_request()
  File "D:\Python\flask_sait\venv\lib\site-packages\flask\app.py", line 1499, in dispatch_request
    return self.ensure_sync(self.view_functions[rule.endpoint])(**req.view_args)
  File "D:\Python\flask_sait\app\auth\routes.py", line 33, in login
    return render_template("auth/login.html", title="Логин", form=form)
  File "D:\Python\flask_sait\venv\lib\site-packages\flask\templating.py", line 147, in render_template
    return _render(
  File "D:\Python\flask_sait\venv\lib\site-packages\flask\templating.py", line 128, in _render
    rv = template.render(context)
  File "D:\Python\flask_sait\venv\lib\site-packages\jinja2\environment.py", line 1304, in render
    self.environment.handle_exception()
  File "D:\Python\flask_sait\venv\lib\site-packages\jinja2\environment.py", line 925, in handle_exception
    raise rewrite_traceback_stack(source=source)
  File "D:\Python\flask_sait\app\templates\auth\login.html", line 2, in top-level template code
    {% import 'bootstrap/wtf.html' as wtf %}
  File "D:\Python\flask_sait\app\templates\base.html", line 1, in top-level template code
    {% extends 'bootstrap/base.html' %}
  File "D:\Python\flask_sait\venv\lib\site-packages\flask_bootstrap\templates\bootstrap\base.html", line 1, in top-level template code
    {% block doc -%}
  File "D:\Python\flask_sait\venv\lib\site-packages\flask_bootstrap\templates\bootstrap\base.html", line 4, in block 'doc'
    {%- block html %}
  File "D:\Python\flask_sait\venv\lib\site-packages\flask_bootstrap\templates\bootstrap\base.html", line 20, in block 'html'
    {% block body -%}
  File "D:\Python\flask_sait\venv\lib\site-packages\flask_bootstrap\templates\bootstrap\base.html", line 21, in block 'body'
    {% block navbar %}
  File "D:\Python\flask_sait\app\templates\base.html", line 17, in block 'navbar'
    <a class="navbar-brand" href="{{ url_for('index') }}">{{ _('Главная') }}</a>
  File "D:\Python\flask_sait\venv\lib\site-packages\flask\helpers.py", line 338, in url_for
    return appctx.app.handle_url_build_error(error, endpoint, values)
  File "D:\Python\flask_sait\venv\lib\site-packages\flask\helpers.py", line 325, in url_for
    rv = url_adapter.build(
  File "D:\Python\flask_sait\venv\lib\site-packages\werkzeug\routing.py", line 2305, in build
    raise BuildError(endpoint, values, method, self)
werkzeug.routing.BuildError: Could not build url for endpoint 'index'. Did you mean 'main.index' instead?
2021-08-18 13:12:57,492 ERROR: Exception on /auth/login [GET][in $(pathname)s: 1454]
Traceback (most recent call last):
  File "D:\Python\flask_sait\venv\lib\site-packages\flask\app.py", line 2070, in wsgi_app
    response = self.full_dispatch_request()
  File "D:\Python\flask_sait\venv\lib\site-packages\flask\app.py", line 1515, in full_dispatch_request
    rv = self.handle_user_exception(e)
  File "D:\Python\flask_sait\venv\lib\site-packages\flask\app.py", line 1513, in full_dispatch_request
    rv = self.dispatch_request()
  File "D:\Python\flask_sait\venv\lib\site-packages\flask\app.py", line 1499, in dispatch_request
    return self.ensure_sync(self.view_functions[rule.endpoint])(**req.view_args)
  File "D:\Python\flask_sait\app\auth\routes.py", line 33, in login
    return render_template("auth/login.html", title="Логин", form=form)
  File "D:\Python\flask_sait\venv\lib\site-packages\flask\templating.py", line 147, in render_template
    return _render(
  File "D:\Python\flask_sait\venv\lib\site-packages\flask\templating.py", line 128, in _render
    rv = template.render(context)
  File "D:\Python\flask_sait\venv\lib\site-packages\jinja2\environment.py", line 1304, in render
    self.environment.handle_exception()
  File "D:\Python\flask_sait\venv\lib\site-packages\jinja2\environment.py", line 925, in handle_exception
    raise rewrite_traceback_stack(source=source)
  File "D:\Python\flask_sait\app\templates\auth\login.html", line 2, in top-level template code
    {% import 'bootstrap/wtf.html' as wtf %}
  File "D:\Python\flask_sait\app\templates\base.html", line 1, in top-level template code
    {% extends 'bootstrap/base.html' %}
  File "D:\Python\flask_sait\venv\lib\site-packages\flask_bootstrap\templates\bootstrap\base.html", line 1, in top-level template code
    {% block doc -%}
  File "D:\Python\flask_sait\venv\lib\site-packages\flask_bootstrap\templates\bootstrap\base.html", line 4, in block 'doc'
    {%- block html %}
  File "D:\Python\flask_sait\venv\lib\site-packages\flask_bootstrap\templates\bootstrap\base.html", line 20, in block 'html'
    {% block body -%}
  File "D:\Python\flask_sait\venv\lib\site-packages\flask_bootstrap\templates\bootstrap\base.html", line 21, in block 'body'
    {% block navbar %}
  File "D:\Python\flask_sait\app\templates\base.html", line 17, in block 'navbar'
    <a class="navbar-brand" href="{{ url_for('index') }}">{{ _('Главная') }}</a>
  File "D:\Python\flask_sait\venv\lib\site-packages\flask\helpers.py", line 338, in url_for
    return appctx.app.handle_url_build_error(error, endpoint, values)
  File "D:\Python\flask_sait\venv\lib\site-packages\flask\helpers.py", line 325, in url_for
    rv = url_adapter.build(
  File "D:\Python\flask_sait\venv\lib\site-packages\werkzeug\routing.py", line 2305, in build
    raise BuildError(endpoint, values, method, self)
werkzeug.routing.BuildError: Could not build url for endpoint 'index'. Did you mean 'main.index' instead?
2021-08-18 13:18:06,598 INFO: Microblog startup[in $(pathname)s: 69]
2021-08-18 13:18:09,754 ERROR: Exception on /auth/login [GET][in $(pathname)s: 1454]
Traceback (most recent call last):
  File "D:\Python\flask_sait\venv\lib\site-packages\flask\app.py", line 2070, in wsgi_app
    response = self.full_dispatch_request()
  File "D:\Python\flask_sait\venv\lib\site-packages\flask\app.py", line 1515, in full_dispatch_request
    rv = self.handle_user_exception(e)
  File "D:\Python\flask_sait\venv\lib\site-packages\flask\app.py", line 1513, in full_dispatch_request
    rv = self.dispatch_request()
  File "D:\Python\flask_sait\venv\lib\site-packages\flask\app.py", line 1499, in dispatch_request
    return self.ensure_sync(self.view_functions[rule.endpoint])(**req.view_args)
  File "D:\Python\flask_sait\app\auth\routes.py", line 33, in login
    return render_template("auth/login.html", title="Логин", form=form)
  File "D:\Python\flask_sait\venv\lib\site-packages\flask\templating.py", line 147, in render_template
    return _render(
  File "D:\Python\flask_sait\venv\lib\site-packages\flask\templating.py", line 128, in _render
    rv = template.render(context)
  File "D:\Python\flask_sait\venv\lib\site-packages\jinja2\environment.py", line 1304, in render
    self.environment.handle_exception()
  File "D:\Python\flask_sait\venv\lib\site-packages\jinja2\environment.py", line 925, in handle_exception
    raise rewrite_traceback_stack(source=source)
  File "D:\Python\flask_sait\app\templates\auth\login.html", line 2, in top-level template code
    {% import 'bootstrap/wtf.html' as wtf %}
  File "D:\Python\flask_sait\app\templates\base.html", line 1, in top-level template code
    {% extends 'bootstrap/base.html' %}
  File "D:\Python\flask_sait\venv\lib\site-packages\flask_bootstrap\templates\bootstrap\base.html", line 1, in top-level template code
    {% block doc -%}
  File "D:\Python\flask_sait\venv\lib\site-packages\flask_bootstrap\templates\bootstrap\base.html", line 4, in block 'doc'
    {%- block html %}
  File "D:\Python\flask_sait\venv\lib\site-packages\flask_bootstrap\templates\bootstrap\base.html", line 20, in block 'html'
    {% block body -%}
  File "D:\Python\flask_sait\venv\lib\site-packages\flask_bootstrap\templates\bootstrap\base.html", line 21, in block 'body'
    {% block navbar %}
  File "D:\Python\flask_sait\app\templates\base.html", line 17, in block 'navbar'
    <a class="navbar-brand" href="{{ url_for('index') }}">{{ _('Главная') }}</a>
  File "D:\Python\flask_sait\venv\lib\site-packages\flask\helpers.py", line 338, in url_for
    return appctx.app.handle_url_build_error(error, endpoint, values)
  File "D:\Python\flask_sait\venv\lib\site-packages\flask\helpers.py", line 325, in url_for
    rv = url_adapter.build(
  File "D:\Python\flask_sait\venv\lib\site-packages\werkzeug\routing.py", line 2305, in build
    raise BuildError(endpoint, values, method, self)
werkzeug.routing.BuildError: Could not build url for endpoint 'index'. Did you mean 'main.index' instead?
2021-08-18 13:27:25,101 INFO: Microblog startup[in $(pathname)s: 69]
2021-08-18 13:27:26,571 INFO: Microblog startup[in $(pathname)s: 69]
2021-08-18 13:29:34,501 INFO: Microblog startup[in $(pathname)s: 69]
2021-08-18 13:29:46,524 INFO: Microblog startup[in $(pathname)s: 69]
2021-08-18 13:30:34,347 INFO: Microblog startup[in $(pathname)s: 69]
2021-08-18 13:56:56,799 INFO: Microblog startup[in $(pathname)s: 69]
2021-08-18 13:56:58,189 INFO: Microblog startup[in $(pathname)s: 69]
2021-08-18 14:32:01,731 INFO: Microblog startup[in $(pathname)s: 69]
2021-08-18 14:32:03,742 INFO: Microblog startup[in $(pathname)s: 69]
2021-08-18 14:45:10,402 INFO: Microblog startup[in $(pathname)s: 69]
2021-08-18 14:45:12,041 INFO: Microblog startup[in $(pathname)s: 69]
2021-08-18 14:52:16,987 INFO: Microblog startup[in $(pathname)s: 69]
2021-08-18 14:52:18,527 INFO: Microblog startup[in $(pathname)s: 69]
2021-08-18 14:54:42,714 INFO: Microblog startup[in $(pathname)s: 69]
2021-08-18 14:54:44,335 INFO: Microblog startup[in $(pathname)s: 69]
2021-08-18 14:57:39,558 INFO: Microblog startup[in $(pathname)s: 69]
